<?xml version="1.0" ?>
<!-- =================================================================================== -->
<!-- |    This document was autogenerated by xacro from iiwa14.xacro                   | -->
<!-- |    EDITING THIS FILE BY HAND IS NOT RECOMMENDED                                 | -->
<!-- =================================================================================== -->
<!-- top level -->
<robot name="iiwa_reflex">
  <!-- KDL requires a link without inertia / Gazebo requires a connection to world link or robot
    will tipple https://github.com/lbr-stack/lbr_fri_ros2_stack/issues/230 -->
  <link name="world"/>
  <!--joint between <robot_name>_world_link and robot_name_link_0-->
  <joint name="lbr_world_joint" type="fixed">
    <parent link="world"/>
    <child link="lbr_link_0"/>
  </joint>
  <link name="lbr_link_0">
    <inertial>
      <origin rpy="0 0 0" xyz="-0.012822 0.0 0.071507"/>
      <mass value="7.050378"/>
      <inertia ixx="0.031226" ixy="0.0" ixz="0.000871" iyy="0.039697" iyz="0.0" izz="0.043102"/>
    </inertial>
    <visual>
      <origin rpy="0 0 0" xyz="0 0 0"/>
      <geometry>
        <mesh filename="lbr_description/meshes/iiwa14/visual/link_0.dae"/>
      </geometry>
    </visual>
    <collision>
      <origin rpy="0 0 0" xyz="0 0 0"/>
      <geometry>
        <mesh filename="lbr_description/meshes/iiwa14/collision/link_0.stl"/>
      </geometry>
    </collision>
  </link>
  <joint name="lbr_A1" type="revolute">
    <origin rpy="0 0 0" xyz="0.0 0.0 0.1475"/>
    <parent link="lbr_link_0"/>
    <child link="lbr_link_1"/>
    <axis xyz="0.0 0.0 1.0"/>
    <limit effort="200" lower="-2.9670597283903604" upper="2.9670597283903604" velocity="1.4835298641951802"/>
    <dynamics damping="10.0" friction="0.1"/>
  </joint>
  <link name="lbr_link_1">
    <inertial>
      <origin rpy="0 0 0" xyz="0.0 -0.033795 0.132404"/>
      <mass value="5.289529"/>
      <inertia ixx="0.042462" ixy="0.0" ixz="0.0" iyy="0.042838" iyz="0.006341" izz="0.01587"/>
    </inertial>
    <visual>
      <origin rpy="0 0 0" xyz="0.0 0.0 -0.1475"/>
      <geometry>
        <mesh filename="lbr_description/meshes/iiwa14/visual/link_1.dae"/>
      </geometry>
    </visual>
    <collision>
      <origin rpy="0 0 0" xyz="0.0 0.0 -0.1475"/>
      <geometry>
        <mesh filename="lbr_description/meshes/iiwa14/collision/link_1.stl"/>
      </geometry>
    </collision>
  </link>
  <joint name="lbr_A2" type="revolute">
    <origin rpy="0 0 0" xyz="0.0 -0.01 0.2125"/>
    <parent link="lbr_link_1"/>
    <child link="lbr_link_2"/>
    <axis xyz="0.0 1.0 0.0"/>
    <limit effort="200" lower="-2.0943951023931953" upper="2.0943951023931953" velocity="1.4835298641951802"/>
    <dynamics damping="10.0" friction="0.1"/>
  </joint>
  <link name="lbr_link_2">
    <inertial>
      <origin rpy="0 0 0" xyz="0.000136 0.047548 0.076322"/>
      <mass value="5.688888"/>
      <inertia ixx="0.055182" ixy="-3.3e-05" ixz="5.6e-05" iyy="0.053983" iyz="0.010034" izz="0.016523"/>
    </inertial>
    <visual>
      <origin rpy="0 0 0" xyz="0.0 0.01 -0.36"/>
      <geometry>
        <mesh filename="lbr_description/meshes/iiwa14/visual/link_2.dae"/>
      </geometry>
    </visual>
    <collision>
      <origin rpy="0 0 0" xyz="0.0 0.01 -0.36"/>
      <geometry>
        <mesh filename="lbr_description/meshes/iiwa14/collision/link_2.stl"/>
      </geometry>
    </collision>
  </link>
  <joint name="lbr_A3" type="revolute">
    <origin rpy="0 0 0" xyz="0.0 0.01 0.228"/>
    <parent link="lbr_link_2"/>
    <child link="lbr_link_3"/>
    <axis xyz="0.0 0.0 1.0"/>
    <limit effort="200" lower="-2.9670597283903604" upper="2.9670597283903604" velocity="1.7453292519943295"/>
    <dynamics damping="10.0" friction="0.1"/>
  </joint>
  <link name="lbr_link_3">
    <inertial>
      <origin rpy="0 0 0" xyz="0.0 0.034913 0.123108"/>
      <mass value="3.461245"/>
      <inertia ixx="0.02172" ixy="0.0" ixz="0.0" iyy="0.02073" iyz="-0.003845" izz="0.007701"/>
    </inertial>
    <visual>
      <origin rpy="0 0 0" xyz="0.0 0.0 -0.588"/>
      <geometry>
        <mesh filename="lbr_description/meshes/iiwa14/visual/link_3.dae"/>
      </geometry>
    </visual>
    <collision>
      <origin rpy="0 0 0" xyz="0.0 0.0 -0.588"/>
      <geometry>
        <mesh filename="lbr_description/meshes/iiwa14/collision/link_3.stl"/>
      </geometry>
    </collision>
  </link>
  <joint name="lbr_A4" type="revolute">
    <origin rpy="0 0 0" xyz="0.0 0.0105 0.192"/>
    <parent link="lbr_link_3"/>
    <child link="lbr_link_4"/>
    <axis xyz="0.0 -1.0 0.0"/>
    <limit effort="200" lower="-2.0943951023931953" upper="2.0943951023931953" velocity="1.3089969389957472"/>
    <dynamics damping="10.0" friction="0.1"/>
  </joint>
  <link name="lbr_link_4">
    <inertial>
      <origin rpy="0 0 0" xyz="0.0 -0.039793 0.086944"/>
      <mass value="4.122995"/>
      <inertia ixx="0.03241" ixy="0.0" ixz="0.0" iyy="0.030758" iyz="-0.006022" izz="0.009883"/>
    </inertial>
    <visual>
      <origin rpy="0 0 0" xyz="0.0 -0.0105 -0.78"/>
      <geometry>
        <mesh filename="lbr_description/meshes/iiwa14/visual/link_4.dae"/>
      </geometry>
    </visual>
    <collision>
      <origin rpy="0 0 0" xyz="0.0 -0.0105 -0.78"/>
      <geometry>
        <mesh filename="lbr_description/meshes/iiwa14/collision/link_4.stl"/>
      </geometry>
    </collision>
  </link>
  <joint name="lbr_A5" type="revolute">
    <origin rpy="0 0 0" xyz="0.0 -0.0105 0.2075"/>
    <parent link="lbr_link_4"/>
    <child link="lbr_link_5"/>
    <axis xyz="0.0 0.0 1.0"/>
    <limit effort="200" lower="-2.9670597283903604" upper="2.9670597283903604" velocity="2.2689280275926285"/>
    <dynamics damping="10.0" friction="0.1"/>
  </joint>
  <link name="lbr_link_5">
    <inertial>
      <origin rpy="0 0 0" xyz="0.0 -0.029824 0.076267"/>
      <mass value="1.563756"/>
      <inertia ixx="0.008677" ixy="0.0" ixz="0.0" iyy="0.007297" iyz="0.002869" izz="0.003935"/>
    </inertial>
    <visual>
      <origin rpy="0 0 0" xyz="0.0 0.0 -0.9875"/>
      <geometry>
        <mesh filename="lbr_description/meshes/iiwa14/visual/link_5.dae"/>
      </geometry>
    </visual>
    <collision>
      <origin rpy="0 0 0" xyz="0.0 0.0 -0.9875"/>
      <geometry>
        <mesh filename="lbr_description/meshes/iiwa14/collision/link_5.stl"/>
      </geometry>
    </collision>
  </link>
  <joint name="lbr_A6" type="revolute">
    <origin rpy="0 0 0" xyz="0.0 -0.0707 0.1925"/>
    <parent link="lbr_link_5"/>
    <child link="lbr_link_6"/>
    <axis xyz="0.0 1.0 0.0"/>
    <limit effort="200" lower="-2.0943951023931953" upper="2.0943951023931953" velocity="2.356194490192345"/>
    <dynamics damping="10.0" friction="0.1"/>
  </joint>
  <link name="lbr_link_6">
    <inertial>
      <origin rpy="0 0 0" xyz="0.0 0.07102 0.00495"/>
      <mass value="2.457878"/>
      <inertia ixx="0.007227" ixy="0.0" ixz="0.0" iyy="0.006958" iyz="0.000318" izz="0.004734"/>
    </inertial>
    <visual>
      <origin rpy="0 0 0" xyz="0.0 0.0707 -1.18"/>
      <geometry>
        <mesh filename="lbr_description/meshes/iiwa14/visual/link_6.dae"/>
      </geometry>
    </visual>
    <collision>
      <origin rpy="0 0 0" xyz="0.0 0.0707 -1.18"/>
      <geometry>
        <mesh filename="lbr_description/meshes/iiwa14/collision/link_6.stl"/>
      </geometry>
    </collision>
  </link>
  <joint name="lbr_A7" type="revolute">
    <origin rpy="0 0 0" xyz="0.0 0.0707 0.091"/>
    <parent link="lbr_link_6"/>
    <child link="lbr_link_7"/>
    <axis xyz="0.0 0.0 1.0"/>
    <limit effort="200" lower="-3.0543261909900763" upper="3.0543261909900763" velocity="2.356194490192345"/>
    <dynamics damping="10.0" friction="0.1"/>
  </joint>
  <link name="lbr_link_7">
    <inertial>
      <origin rpy="0 0 0" xyz="3.0000e-06 -2.0000e-06 1.3782e-02"/>
      <mass value="0.265331"/>
      <inertia ixx="0.000175" ixy="0.0" ixz="0.0" iyy="0.000175" iyz="0.0" izz="0.000306"/>
    </inertial>
    <visual>
      <origin rpy="0 0 0" xyz="0.0 0.0 -1.271"/>
      <geometry>
        <mesh filename="lbr_description/meshes/iiwa14/visual/link_7.dae"/>
      </geometry>
    </visual>
    <collision>
      <origin rpy="0 0 0" xyz="0.0 0.0 -1.271"/>
      <geometry>
        <mesh filename="lbr_description/meshes/iiwa14/collision/link_7.stl"/>
      </geometry>
    </collision>
  </link>
  <joint name="lbr_joint_ee" type="fixed">
    <parent link="lbr_link_7"/>
    <child link="lbr_link_ee"/>
    <origin rpy="0 0 0" xyz="0 0 0.035"/>
  </joint>
  <link name="lbr_link_ee">
  </link>

  <!-- Reflex gripper -->
  <link name="reflex_shell_link">
    <visual>
      <origin rpy="0 0 0" xyz="0 0 0"/>
      <geometry>
        <mesh filename="lbr_description/meshes/reflex/collision/base_link.stl"/>
      </geometry>
      <material name="black"/>
    </visual>
    <inertial>
      <origin rpy="0 0 0" xyz="0 0 0"/>
      <mass value="0.74"/>
      <inertia ixx="0.00165124833333" ixy="0.0" ixz="0.0" iyy="0.00140920666667" iyz="0.0" izz="0.000779281666667"/>
    </inertial>
    <collision>
      <origin rpy="0 0 0" xyz="0 0 0"/>
      <geometry>
        <mesh filename="lbr_description/meshes/reflex/collision/base_link_coll.stl"/>
      </geometry>
    </collision>
  </link>
  <joint name="reflex_shell_to_pad_joint" type="fixed">
    <origin rpy="1.5707963268 0 -1.5707963268" xyz="0.02 0 0.063"/>
    <parent link="reflex_shell_link"/>
    <child link="reflex_pad_link"/>
    <axis xyz="0 0 0"/>
  </joint>
  <link name="reflex_pad_link">
    <visual>
      <origin rpy="0 0 0" xyz="0 0 0"/>
      <geometry>
        <mesh filename="lbr_description/meshes/reflex/collision/pad.stl"/>
      </geometry>
      <material name="dark_grey">
        <color rgba="0.2 0.2 0.2 1"/>
      </material>
    </visual>
    <inertial>
      <origin rpy="0 0 0" xyz="0 0 0"/>
      <mass value="0.1"/>
      <inertia ixx="0.000223141666667" ixy="0.0" ixz="0.0" iyy="0.000190433333333" iyz="0.0" izz="0.000105308333333"/>
    </inertial>
    <collision>
      <origin rpy="0 0 0" xyz="0 0 0"/>
      <geometry>
        <mesh filename="lbr_description/meshes/reflex/collision/pad_coll.stl"/>
      </geometry>
    </collision>
  </link>
  <joint name="reflex_palm_joint" type="fixed">
    <origin rpy="3.14159265359 0 1.5707963268" xyz="0 0 0"/>
    <parent link="reflex_pad_link"/>
    <child link="reflex_palm_link"/>
    <axis xyz="0 0 0"/>
  </joint>
  <link name="reflex_palm_link"/>
  <!-- A dummy link to define the end-effector frame -->
  <joint name="reflex_preshape_joint_1" type="revolute">
    <parent link="reflex_shell_link"/>
    <child link="reflex_swivel_link_1"/>
    <limit effort="15" lower="0.0" upper="1.5707963268" velocity="7"/>
    <dynamics damping="5"/>
    <origin rpy="0 0 0" xyz="0.0503973683071414 -0.026 0.063"/>
    <axis xyz="0 0 -1"/>
  </joint>
  <link name="reflex_swivel_link_1">
    <visual>
      <origin rpy="0 0 0" xyz="0 0 0"/>
      <geometry>
        <mesh filename="lbr_description/meshes/reflex/collision/swivel_1.stl"/>
      </geometry>
      <material name="black"/>
    </visual>
    <inertial>
      <origin rpy="0 0 0" xyz="0 0 0"/>
      <mass value="0.01"/>
      <inertia ixx="1.60333333333e-06" ixy="0.0" ixz="0.0" iyy="1.15333333333e-06" iyz="0.0" izz="1.25666666667e-06"/>
    </inertial>
    <collision>
      <origin rpy="0 0 0" xyz="0 0 0"/>
      <geometry>
        <mesh filename="lbr_description/meshes/reflex/collision/swivel_1_coll.stl"/>
      </geometry>
    </collision>
  </link>
  <joint name="reflex_proximal_joint_1" type="revolute">
    <child link="reflex_proximal_link_1"/>
    <axis xyz="0 -1 0"/>
    <limit effort="15" lower="0.0" upper="3.14159265359" velocity="7"/>
    <dynamics damping="5"/>
    <origin rpy="0 0.28 0" xyz="0.01 0 0.0186"/>
    <parent link="reflex_swivel_link_1"/>
  </joint>
  <link name="reflex_proximal_link_1">
    <visual>
      <origin rpy="3.14159265359 0 0" xyz="-0.011 0.007 0.011"/>
      <geometry>
        <mesh filename="lbr_description/meshes/reflex/collision/proximal.stl"/>
      </geometry>
      <material name="black"/>
    </visual>
    <inertial>
      <origin rpy="3.14159265359 0 0" xyz="-0.011 0.007 0.011"/>
      <mass value="0.01"/>
      <inertia ixx="2.29508333333e-05" ixy="0.0" ixz="0.0" iyy="4.53416666667e-06" iyz="0.0" izz="1.90833333333e-05"/>
    </inertial>
    <collision>
      <origin rpy="3.14159265359 0 0" xyz="-0.011 0.007 0.011"/>
      <geometry>
        <mesh filename="lbr_description/meshes/reflex/collision/proximal_coll.stl"/>
      </geometry>
    </collision>
  </link>
  <joint name="reflex_proximal_1_to_pad" type="fixed">
    <origin rpy="1.5707963268 0 -1.5707963268" xyz="0 0 0"/>
    <parent link="reflex_proximal_link_1"/>
    <child link="reflex_proximal_pad_link_1"/>
  </joint>
  <link name="reflex_proximal_pad_link_1">
    <visual>
      <origin rpy="1.5707963268 1.5707963268 0" xyz="-0.008 0.014 -0.002"/>
      <geometry>
        <mesh filename="lbr_description/meshes/reflex/collision/proximal_pad.stl"/>
      </geometry>
      <material name="dark_grey">
        <color rgba="0.2 0.2 0.2 1"/>
      </material>
    </visual>
    <inertial>
      <origin rpy="1.5707963268 1.5707963268 0" xyz="-0.008 0.014 -0.002"/>
      <mass value="0.01"/>
      <inertia ixx="2.29508333333e-05" ixy="0.0" ixz="0.0" iyy="4.22166666667e-06" iyz="0.0" izz="1.87708333333e-05"/>
    </inertial>
    <collision>
      <origin rpy="1.5707963268 1.5707963268 0" xyz="-0.008 0.014 -0.002"/>
      <geometry>
        <mesh filename="lbr_description/meshes/reflex/collision/proximal_pad_coll.stl"/>
      </geometry>
    </collision>
  </link>
  <joint name="reflex_proximal_1_to_flex" type="fixed">
    <origin rpy="0 0 0" xyz="0.07 0 0.004"/>
    <parent link="reflex_proximal_link_1"/>
    <child link="reflex_flex_link_1"/>
  </joint>
  <link name="reflex_flex_link_1">
    <visual>
      <origin rpy="0 0 0" xyz="0.0005 0 -0.003"/>
      <geometry>
        <box size="0.017 0.014 0.0065"/>
      </geometry>
      <material name="gold">
        <color rgba="0.996078431373 0.847058823529 0.364705882353 1"/>
      </material>
    </visual>
    <inertial>
      <origin rpy="0 0 0" xyz="0 0 0"/>
      <mass value="0.01"/>
      <inertia ixx="3.50833333333e-07" ixy="0.0" ixz="0.0" iyy="2.08333333333e-07" iyz="0.0" izz="1.84166666667e-07"/>
    </inertial>
    <collision>
      <origin rpy="0 0 0" xyz="0 0 0"/>
      <geometry>
        <box size="0.01 0.01 0.01"/>
      </geometry>
    </collision>
  </link>
  <joint name="reflex_flex_to_distal_1" type="fixed">
    <origin rpy="0 0 0" xyz="0 0 0"/>
    <parent link="reflex_flex_link_1"/>
    <child link="reflex_distal_link_1"/>
  </joint>
  <link name="reflex_distal_link_1">
    <visual>
      <origin rpy="3.14159265359 0 0" xyz="-0.077 0.007 0.007"/>
      <geometry>
        <mesh filename="lbr_description/meshes/reflex/collision/distal.stl"/>
      </geometry>
      <material name="black"/>
    </visual>
    <inertial>
      <origin rpy="3.1459 0 0" xyz="-0.077 0.007 0.007"/>
      <mass value="0.01"/>
      <inertia ixx="2.00175e-05" ixy="0.0" ixz="0.0" iyy="1.50833333333e-06" iyz="0.0" izz="1.89908333333e-05"/>
    </inertial>
    <collision>
      <origin rpy="3.14159265359 0 0" xyz="-0.077 0.007 0.007"/>
      <geometry>
        <mesh filename="lbr_description/meshes/reflex/collision/distal_coll.stl"/>
      </geometry>
    </collision>
  </link>
  <joint name="reflex_distal_1_to_pad" type="fixed">
    <origin rpy="1.5707963268 0 -1.5707963268" xyz="-0.01 0 0.001"/>
    <parent link="reflex_distal_link_1"/>
    <child link="reflex_distal_pad_link_1"/>
  </joint>
  <link name="reflex_distal_pad_link_1">
    <visual>
      <origin rpy="1.5707963268 1.5707963268 0" xyz="-0.00825 0.009 0.057"/>
      <geometry>
        <mesh filename="lbr_description/meshes/reflex/collision/distal_pad.stl"/>
      </geometry>
      <material name="dark_grey">
        <color rgba="0.2 0.2 0.2 1"/>
      </material>
    </visual>
    <inertial>
      <origin rpy="1.5707963268 1.5707963268 0" xyz="-0.00825 0.009 0.057"/>
      <mass value="0.01"/>
      <inertia ixx="2.00175e-05" ixy="0.0" ixz="0.0" iyy="1.28833333333e-06" iyz="0.0" izz="1.87708333333e-05"/>
    </inertial>
    <collision>
      <origin rpy="1.5707963268 1.5707963268 0" xyz="-0.00825 0.009 0.057"/>
      <geometry>
        <mesh filename="lbr_description/meshes/reflex/collision/distal_pad_coll.stl"/>
      </geometry>
    </collision>
  </link>
  <joint name="reflex_preshape_joint_2" type="revolute">
    <parent link="reflex_shell_link"/>
    <child link="reflex_swivel_link_2"/>
    <limit effort="15" lower="0.0" upper="1.5707963268" velocity="7"/>
    <dynamics damping="5"/>
    <origin rpy="0 0 0" xyz="0.0503973683071413 0.026 0.063"/>
    <axis xyz="0 0 1"/>
  </joint>
  <link name="reflex_swivel_link_2">
    <visual>
      <origin rpy="0 0 0" xyz="0 0 0"/>
      <geometry>
        <mesh filename="lbr_description/meshes/reflex/collision/swivel_2.stl"/>
      </geometry>
      <material name="black"/>
    </visual>
    <inertial>
      <origin rpy="0 0 0" xyz="0 0 0"/>
      <mass value="0.01"/>
      <inertia ixx="1.60333333333e-06" ixy="0.0" ixz="0.0" iyy="1.15333333333e-06" iyz="0.0" izz="1.25666666667e-06"/>
    </inertial>
    <collision>
      <origin rpy="0 0 0" xyz="0 0 0"/>
      <geometry>
        <mesh filename="lbr_description/meshes/reflex/collision/swivel_2_coll.stl"/>
      </geometry>
    </collision>
  </link>
  <joint name="reflex_proximal_joint_2" type="revolute">
    <child link="reflex_proximal_link_2"/>
    <axis xyz="0 -1 0"/>
    <limit effort="15" lower="0.0" upper="3.14159265359" velocity="7"/>
    <dynamics damping="5"/>
    <origin rpy="0 0.28 0" xyz="0.01 0 0.0186"/>
    <parent link="reflex_swivel_link_2"/>
  </joint>
  <link name="reflex_proximal_link_2">
    <visual>
      <origin rpy="3.14159265359 0 0" xyz="-0.011 0.007 0.011"/>
      <geometry>
        <mesh filename="lbr_description/meshes/reflex/collision/proximal.stl"/>
      </geometry>
      <material name="black"/>
    </visual>
    <inertial>
      <origin rpy="3.14159265359 0 0" xyz="-0.011 0.007 0.011"/>
      <mass value="0.01"/>
      <inertia ixx="2.29508333333e-05" ixy="0.0" ixz="0.0" iyy="4.53416666667e-06" iyz="0.0" izz="1.90833333333e-05"/>
    </inertial>
    <collision>
      <origin rpy="3.14159265359 0 0" xyz="-0.011 0.007 0.011"/>
      <geometry>
        <mesh filename="lbr_description/meshes/reflex/collision/proximal_coll.stl"/>
      </geometry>
    </collision>
  </link>
  <joint name="reflex_proximal_2_to_pad" type="fixed">
    <origin rpy="1.5707963268 0 -1.5707963268" xyz="0 0 0"/>
    <parent link="reflex_proximal_link_2"/>
    <child link="reflex_proximal_pad_link_2"/>
  </joint>
  <link name="reflex_proximal_pad_link_2">
    <visual>
      <origin rpy="1.5707963268 1.5707963268 0" xyz="-0.008 0.014 -0.002"/>
      <geometry>
        <mesh filename="lbr_description/meshes/reflex/collision/proximal_pad.stl"/>
      </geometry>
      <material name="dark_grey">
        <color rgba="0.2 0.2 0.2 1"/>
      </material>
    </visual>
    <inertial>
      <origin rpy="1.5707963268 1.5707963268 0" xyz="-0.008 0.014 -0.002"/>
      <mass value="0.01"/>
      <inertia ixx="2.29508333333e-05" ixy="0.0" ixz="0.0" iyy="4.22166666667e-06" iyz="0.0" izz="1.87708333333e-05"/>
    </inertial>
    <collision>
      <origin rpy="1.5707963268 1.5707963268 0" xyz="-0.008 0.014 -0.002"/>
      <geometry>
        <mesh filename="lbr_description/meshes/reflex/collision/proximal_pad_coll.stl"/>
      </geometry>
    </collision>
  </link>
  <joint name="reflex_proximal_2_to_flex" type="fixed">
    <origin rpy="0 0 0" xyz="0.07 0 0.004"/>
    <parent link="reflex_proximal_link_2"/>
    <child link="reflex_flex_link_2"/>
  </joint>
  <link name="reflex_flex_link_2">
    <visual>
      <origin rpy="0 0 0" xyz="0.0005 0 -0.003"/>
      <geometry>
        <box size="0.017 0.014 0.0065"/>
      </geometry>
      <material name="gold">
        <color rgba="0.996078431373 0.847058823529 0.364705882353 1"/>
      </material>
    </visual>
    <inertial>
      <origin rpy="0 0 0" xyz="0 0 0"/>
      <mass value="0.01"/>
      <inertia ixx="3.50833333333e-07" ixy="0.0" ixz="0.0" iyy="2.08333333333e-07" iyz="0.0" izz="1.84166666667e-07"/>
    </inertial>
    <collision>
      <origin rpy="0 0 0" xyz="0 0 0"/>
      <geometry>
        <box size="0.01 0.01 0.01"/>
      </geometry>
    </collision>
  </link>
  <joint name="reflex_flex_to_distal_2" type="fixed">
    <origin rpy="0 0 0" xyz="0 0 0"/>
    <parent link="reflex_flex_link_2"/>
    <child link="reflex_distal_link_2"/>
  </joint>
  <link name="reflex_distal_link_2">
    <visual>
      <origin rpy="3.14159265359 0 0" xyz="-0.077 0.007 0.007"/>
      <geometry>
        <mesh filename="lbr_description/meshes/reflex/collision/distal.stl"/>
      </geometry>
      <material name="black"/>
    </visual>
    <inertial>
      <origin rpy="3.1459 0 0" xyz="-0.077 0.007 0.007"/>
      <mass value="0.01"/>
      <inertia ixx="2.00175e-05" ixy="0.0" ixz="0.0" iyy="1.50833333333e-06" iyz="0.0" izz="1.89908333333e-05"/>
    </inertial>
    <collision>
      <origin rpy="3.14159265359 0 0" xyz="-0.077 0.007 0.007"/>
      <geometry>
        <mesh filename="lbr_description/meshes/reflex/collision/distal_coll.stl"/>
      </geometry>
    </collision>
  </link>
  <joint name="reflex_distal_2_to_pad" type="fixed">
    <origin rpy="1.5707963268 0 -1.5707963268" xyz="-0.01 0 0.001"/>
    <parent link="reflex_distal_link_2"/>
    <child link="reflex_distal_pad_link_2"/>
  </joint>
  <link name="reflex_distal_pad_link_2">
    <visual>
      <origin rpy="1.5707963268 1.5707963268 0" xyz="-0.00825 0.009 0.057"/>
      <geometry>
        <mesh filename="lbr_description/meshes/reflex/collision/distal_pad.stl"/>
      </geometry>
      <material name="dark_grey">
        <color rgba="0.2 0.2 0.2 1"/>
      </material>
    </visual>
    <inertial>
      <origin rpy="1.5707963268 1.5707963268 0" xyz="-0.00825 0.009 0.057"/>
      <mass value="0.01"/>
      <inertia ixx="2.00175e-05" ixy="0.0" ixz="0.0" iyy="1.28833333333e-06" iyz="0.0" izz="1.87708333333e-05"/>
    </inertial>
    <collision>
      <origin rpy="1.5707963268 1.5707963268 0" xyz="-0.00825 0.009 0.057"/>
      <geometry>
        <mesh filename="lbr_description/meshes/reflex/collision/distal_pad_coll.stl"/>
      </geometry>
    </collision>
  </link>
  <joint name="reflex_proximal_joint_3" type="revolute">
    <child link="reflex_proximal_link_3"/>
    <axis xyz="0 -1 0"/>
    <limit effort="15" lower="0.0" upper="3.14159265359" velocity="7"/>
    <dynamics damping="5"/>
    <origin rpy="0 0.28 3.14159265359" xyz="-0.03 0 0.0816"/>
    <parent link="reflex_shell_link"/>
  </joint>
  <link name="reflex_proximal_link_3">
    <visual>
      <origin rpy="3.14159265359 0 0" xyz="-0.011 0.007 0.011"/>
      <geometry>
        <mesh filename="lbr_description/meshes/reflex/collision/proximal.stl"/>
      </geometry>
      <material name="black"/>
    </visual>
    <inertial>
      <origin rpy="3.14159265359 0 0" xyz="-0.011 0.007 0.011"/>
      <mass value="0.01"/>
      <inertia ixx="2.29508333333e-05" ixy="0.0" ixz="0.0" iyy="4.53416666667e-06" iyz="0.0" izz="1.90833333333e-05"/>
    </inertial>
    <collision>
      <origin rpy="3.14159265359 0 0" xyz="-0.011 0.007 0.011"/>
      <geometry>
        <mesh filename="lbr_description/meshes/reflex/collision/proximal_coll.stl"/>
      </geometry>
    </collision>
  </link>
  <joint name="reflex_proximal_3_to_pad" type="fixed">
    <origin rpy="1.5707963268 0 -1.5707963268" xyz="0 0 0"/>
    <parent link="reflex_proximal_link_3"/>
    <child link="reflex_proximal_pad_link_3"/>
  </joint>
  <link name="reflex_proximal_pad_link_3">
    <visual>
      <origin rpy="1.5707963268 1.5707963268 0" xyz="-0.008 0.014 -0.002"/>
      <geometry>
        <mesh filename="lbr_description/meshes/reflex/collision/proximal_pad.stl"/>
      </geometry>
      <material name="dark_grey">
        <color rgba="0.2 0.2 0.2 1"/>
      </material>
    </visual>
    <inertial>
      <origin rpy="1.5707963268 1.5707963268 0" xyz="-0.008 0.014 -0.002"/>
      <mass value="0.01"/>
      <inertia ixx="2.29508333333e-05" ixy="0.0" ixz="0.0" iyy="4.22166666667e-06" iyz="0.0" izz="1.87708333333e-05"/>
    </inertial>
    <collision>
      <origin rpy="1.5707963268 1.5707963268 0" xyz="-0.008 0.014 -0.002"/>
      <geometry>
        <mesh filename="lbr_description/meshes/reflex/collision/proximal_pad_coll.stl"/>
      </geometry>
    </collision>
  </link>
  <joint name="reflex_proximal_3_to_flex" type="fixed">
    <origin rpy="0 0 0" xyz="0.07 0 0.004"/>
    <parent link="reflex_proximal_link_3"/>
    <child link="reflex_flex_link_3"/>
  </joint>
  <link name="reflex_flex_link_3">
    <visual>
      <origin rpy="0 0 0" xyz="0.0005 0 -0.003"/>
      <geometry>
        <box size="0.017 0.014 0.0065"/>
      </geometry>
      <material name="gold">
        <color rgba="0.996078431373 0.847058823529 0.364705882353 1"/>
      </material>
    </visual>
    <inertial>
      <origin rpy="0 0 0" xyz="0 0 0"/>
      <mass value="0.01"/>
      <inertia ixx="3.50833333333e-07" ixy="0.0" ixz="0.0" iyy="2.08333333333e-07" iyz="0.0" izz="1.84166666667e-07"/>
    </inertial>
    <collision>
      <origin rpy="0 0 0" xyz="0 0 0"/>
      <geometry>
        <box size="0.01 0.01 0.01"/>
      </geometry>
    </collision>
  </link>
  <joint name="reflex_flex_to_distal_3" type="fixed">
    <origin rpy="0 0 0" xyz="0 0 0"/>
    <parent link="reflex_flex_link_3"/>
    <child link="reflex_distal_link_3"/>
  </joint>
  <link name="reflex_distal_link_3">
    <visual>
      <origin rpy="3.14159265359 0 0" xyz="-0.077 0.007 0.007"/>
      <geometry>
        <mesh filename="lbr_description/meshes/reflex/collision/distal.stl"/>
      </geometry>
      <material name="black"/>
    </visual>
    <inertial>
      <origin rpy="3.1459 0 0" xyz="-0.077 0.007 0.007"/>
      <mass value="0.01"/>
      <inertia ixx="2.00175e-05" ixy="0.0" ixz="0.0" iyy="1.50833333333e-06" iyz="0.0" izz="1.89908333333e-05"/>
    </inertial>
    <collision>
      <origin rpy="3.14159265359 0 0" xyz="-0.077 0.007 0.007"/>
      <geometry>
        <mesh filename="lbr_description/meshes/reflex/collision/distal_coll.stl"/>
      </geometry>
    </collision>
  </link>
  <joint name="reflex_distal_3_to_pad" type="fixed">
    <origin rpy="1.5707963268 0 -1.5707963268" xyz="-0.01 0 0.001"/>
    <parent link="reflex_distal_link_3"/>
    <child link="reflex_distal_pad_link_3"/>
  </joint>
  <link name="reflex_distal_pad_link_3">
    <visual>
      <origin rpy="1.5707963268 1.5707963268 0" xyz="-0.00825 0.009 0.057"/>
      <geometry>
        <mesh filename="lbr_description/meshes/reflex/collision/distal_pad.stl"/>
      </geometry>
      <material name="dark_grey">
        <color rgba="0.2 0.2 0.2 1"/>
      </material>
    </visual>
    <inertial>
      <origin rpy="1.5707963268 1.5707963268 0" xyz="-0.00825 0.009 0.057"/>
      <mass value="0.01"/>
      <inertia ixx="2.00175e-05" ixy="0.0" ixz="0.0" iyy="1.28833333333e-06" iyz="0.0" izz="1.87708333333e-05"/>
    </inertial>
    <collision>
      <origin rpy="1.5707963268 1.5707963268 0" xyz="-0.00825 0.009 0.057"/>
      <geometry>
        <mesh filename="lbr_description/meshes/reflex/collision/distal_pad_coll.stl"/>
      </geometry>
    </collision>
  </link>
  <!-- Mount + screws -->
  <link name="reflex2_to_iiwa_mount">
    <inertial>
      <origin rpy="0 0 0" xyz="0 0 0"/>
      <mass value="0.064"/>
      <inertia ixx="2.0368e-05" ixy="0.0" ixz="0.0" iyy="2.0368e-05" iyz="0.0" izz="3.92e-05"/>
    </inertial>
    <visual>
      <origin rpy="0 0 0" xyz="0 0 0"/>
      <geometry>
        <cylinder length="0.012" radius="0.035"/>
      </geometry>
      <material name="black"/>
    </visual>
    <collision>
      <origin rpy="0 0 0" xyz="0 0 0"/>
      <geometry>
        <cylinder length="0.012" radius="0.035"/>
      </geometry>
    </collision>
  </link>
  <!-- Made up value -->
  <link name="reflex2_extra_shell">
    <inertial>
      <origin rpy="0 0 0" xyz="0 0 0"/>
      <mass value="0.01"/>
      <inertia ixx="4.02083333333e-06" ixy="0.0" ixz="0.0" iyy="4.02083333333e-06" iyz="0.0" izz="8e-06"/>
    </inertial>
    <visual>
      <origin rpy="0 0 0" xyz="0 0 0"/>
      <geometry>
        <cylinder length="0.005" radius="0.04"/>
      </geometry>
      <material name="black"/>
    </visual>
    <collision>
      <origin rpy="0 0 0" xyz="0 0 0"/>
      <geometry>
        <cylinder length="0.005" radius="0.04"/>
      </geometry>
    </collision>
  </link>
  <joint name="iiwa_to_mount" type="fixed">
    <parent link="lbr_link_ee"/>
    <child link="reflex2_to_iiwa_mount"/>
    <origin rpy="0 0 0" xyz="0 0 0.006"/>
  </joint>
  <joint name="mount_to_extra_shell" type="fixed">
    <parent link="reflex2_to_iiwa_mount"/>
    <child link="reflex2_extra_shell"/>
    <origin rpy="0 0 0" xyz="0 0 0.0085"/>
  </joint>
  <joint name="extra_shell_to_reflex" type="fixed">
    <parent link="reflex2_extra_shell"/>
    <child link="reflex_shell_link"/>
    <origin rpy="0 0 3.14159265359" xyz="0.014 0 0.0025"/>
  </joint>
</robot>