<?xml version="1.0" ?>
<!-- =================================================================================== -->
<!-- |    This document was autogenerated by xacro from iiwa14.xacro                   | -->
<!-- |    EDITING THIS FILE BY HAND IS NOT RECOMMENDED                                 | -->
<!-- =================================================================================== -->
<!-- top level -->
<robot name="iiwa_robotiq">
  <!-- KDL requires a link without inertia / Gazebo requires a connection to world link or robot
    will tipple https://github.com/lbr-stack/lbr_fri_ros2_stack/issues/230 -->
  <link name="world"/>
  <!--joint between <robot_name>_world_link and robot_name_link_0-->
  <joint name="lbr_world_joint" type="fixed">
    <origin rpy="0 0 3.14" xyz="0 0 0"/>
    <parent link="world"/>
    <child link="lbr_link_0"/>
  </joint>
  <link name="lbr_link_0">
    <inertial>
      <origin rpy="0 0 0" xyz="-0.012822 0.0 0.071507"/>
      <mass value="7.050378"/>
      <inertia ixx="0.031226" ixy="0.0" ixz="0.000871" iyy="0.039697" iyz="0.0" izz="0.043102"/>
    </inertial>
    <visual>
      <origin rpy="0 0 0" xyz="0 0 0"/>
      <geometry>
	      <mesh filename="lbr_description/meshes/iiwa14/visual/link_0.dae"/>
      </geometry>
    </visual>
    <collision>
      <origin rpy="0 0 0" xyz="0 0 0"/>
      <geometry>
	      <mesh filename="lbr_description/meshes/iiwa14/collision/link_0.stl"/>
      </geometry>
    </collision>
  </link>
  <joint name="lbr_A1" type="revolute">
    <origin rpy="0 0 0" xyz="0.0 0.0 0.1475"/>
    <parent link="lbr_link_0"/>
    <child link="lbr_link_1"/>
    <axis xyz="0.0 0.0 1.0"/>
    <limit effort="200" lower="-2.9670597283903604" upper="2.9670597283903604" velocity="1.4835298641951802"/>
    <dynamics damping="10.0" friction="0.1"/>
  </joint>
  <link name="lbr_link_1">
    <inertial>
      <origin rpy="0 0 0" xyz="0.0 -0.033795 0.132404"/>
      <mass value="5.289529"/>
      <inertia ixx="0.042462" ixy="0.0" ixz="0.0" iyy="0.042838" iyz="0.006341" izz="0.01587"/>
    </inertial>
    <visual>
      <origin rpy="0 0 0" xyz="0.0 0.0 -0.1475"/>
      <geometry>
        <mesh filename="lbr_description/meshes/iiwa14/visual/link_1.dae"/>
      </geometry>
    </visual>
    <collision>
      <origin rpy="0 0 0" xyz="0.0 0.0 -0.1475"/>
      <geometry>
        <mesh filename="lbr_description/meshes/iiwa14/collision/link_1.stl"/>
      </geometry>
    </collision>
  </link>
  <joint name="lbr_A2" type="revolute">
    <origin rpy="0 0 0" xyz="0.0 -0.01 0.2125"/>
    <parent link="lbr_link_1"/>
    <child link="lbr_link_2"/>
    <axis xyz="0.0 1.0 0.0"/>
    <limit effort="200" lower="-2.0943951023931953" upper="2.0943951023931953" velocity="1.4835298641951802"/>
    <dynamics damping="10.0" friction="0.1"/>
  </joint>
  <link name="lbr_link_2">
    <inertial>
      <origin rpy="0 0 0" xyz="0.000136 0.047548 0.076322"/>
      <mass value="5.688888"/>
      <inertia ixx="0.055182" ixy="-3.3e-05" ixz="5.6e-05" iyy="0.053983" iyz="0.010034" izz="0.016523"/>
    </inertial>
    <visual>
      <origin rpy="0 0 0" xyz="0.0 0.01 -0.36"/>
      <geometry>
        <mesh filename="lbr_description/meshes/iiwa14/visual/link_2.dae"/>
      </geometry>
    </visual>
    <collision>
      <origin rpy="0 0 0" xyz="0.0 0.01 -0.36"/>
      <geometry>
        <mesh filename="lbr_description/meshes/iiwa14/collision/link_2.stl"/>
      </geometry>
    </collision>
  </link>
  <joint name="lbr_A3" type="revolute">
    <origin rpy="0 0 0" xyz="0.0 0.01 0.228"/>
    <parent link="lbr_link_2"/>
    <child link="lbr_link_3"/>
    <axis xyz="0.0 0.0 1.0"/>
    <limit effort="200" lower="-2.9670597283903604" upper="2.9670597283903604" velocity="1.7453292519943295"/>
    <dynamics damping="10.0" friction="0.1"/>
  </joint>
  <link name="lbr_link_3">
    <inertial>
      <origin rpy="0 0 0" xyz="0.0 0.034913 0.123108"/>
      <mass value="3.461245"/>
      <inertia ixx="0.02172" ixy="0.0" ixz="0.0" iyy="0.02073" iyz="-0.003845" izz="0.007701"/>
    </inertial>
    <visual>
      <origin rpy="0 0 0" xyz="0.0 0.0 -0.588"/>
      <geometry>
        <mesh filename="lbr_description/meshes/iiwa14/visual/link_3.dae"/>
      </geometry>
    </visual>
    <collision>
      <origin rpy="0 0 0" xyz="0.0 0.0 -0.588"/>
      <geometry>
        <mesh filename="lbr_description/meshes/iiwa14/collision/link_3.stl"/>
      </geometry>
    </collision>
  </link>
  <joint name="lbr_A4" type="revolute">
    <origin rpy="0 0 0" xyz="0.0 0.0105 0.192"/>
    <parent link="lbr_link_3"/>
    <child link="lbr_link_4"/>
    <axis xyz="0.0 -1.0 0.0"/>
    <limit effort="200" lower="-2.0943951023931953" upper="2.0943951023931953" velocity="1.3089969389957472"/>
    <dynamics damping="10.0" friction="0.1"/>
  </joint>
  <link name="lbr_link_4">
    <inertial>
      <origin rpy="0 0 0" xyz="0.0 -0.039793 0.086944"/>
      <mass value="4.122995"/>
      <inertia ixx="0.03241" ixy="0.0" ixz="0.0" iyy="0.030758" iyz="-0.006022" izz="0.009883"/>
    </inertial>
    <visual>
      <origin rpy="0 0 0" xyz="0.0 -0.0105 -0.78"/>
      <geometry>
        <mesh filename="lbr_description/meshes/iiwa14/visual/link_4.dae"/>
      </geometry>
    </visual>
    <collision>
      <origin rpy="0 0 0" xyz="0.0 -0.0105 -0.78"/>
      <geometry>
        <mesh filename="lbr_description/meshes/iiwa14/collision/link_4.stl"/>
      </geometry>
    </collision>
  </link>
  <joint name="lbr_A5" type="revolute">
    <origin rpy="0 0 0" xyz="0.0 -0.0105 0.2075"/>
    <parent link="lbr_link_4"/>
    <child link="lbr_link_5"/>
    <axis xyz="0.0 0.0 1.0"/>
    <limit effort="200" lower="-2.9670597283903604" upper="2.9670597283903604" velocity="2.2689280275926285"/>
    <dynamics damping="10.0" friction="0.1"/>
  </joint>
  <link name="lbr_link_5">
    <inertial>
      <origin rpy="0 0 0" xyz="0.0 -0.029824 0.076267"/>
      <mass value="1.563756"/>
      <inertia ixx="0.008677" ixy="0.0" ixz="0.0" iyy="0.007297" iyz="0.002869" izz="0.003935"/>
    </inertial>
    <visual>
      <origin rpy="0 0 0" xyz="0.0 0.0 -0.9875"/>
      <geometry>
        <mesh filename="lbr_description/meshes/iiwa14/visual/link_5.dae"/>
      </geometry>
    </visual>
    <collision>
      <origin rpy="0 0 0" xyz="0.0 0.0 -0.9875"/>
      <geometry>
        <mesh filename="lbr_description/meshes/iiwa14/collision/link_5.stl"/>
      </geometry>
    </collision>
  </link>
  <joint name="lbr_A6" type="revolute">
    <origin rpy="0 0 0" xyz="0.0 -0.0707 0.1925"/>
    <parent link="lbr_link_5"/>
    <child link="lbr_link_6"/>
    <axis xyz="0.0 1.0 0.0"/>
    <limit effort="200" lower="-2.0943951023931953" upper="2.0943951023931953" velocity="2.356194490192345"/>
    <dynamics damping="10.0" friction="0.1"/>
  </joint>
  <link name="lbr_link_6">
    <inertial>
      <origin rpy="0 0 0" xyz="0.0 0.07102 0.00495"/>
      <mass value="2.457878"/>
      <inertia ixx="0.007227" ixy="0.0" ixz="0.0" iyy="0.006958" iyz="0.000318" izz="0.004734"/>
    </inertial>
    <visual>
      <origin rpy="0 0 0" xyz="0.0 0.0707 -1.18"/>
      <geometry>
        <mesh filename="lbr_description/meshes/iiwa14/visual/link_6.dae"/>
      </geometry>
    </visual>
    <collision>
      <origin rpy="0 0 0" xyz="0.0 0.0707 -1.18"/>
      <geometry>
        <mesh filename="lbr_description/meshes/iiwa14/collision/link_6.stl"/>
      </geometry>
    </collision>
  </link>
  <joint name="lbr_A7" type="revolute">
    <origin rpy="0 0 0" xyz="0.0 0.0707 0.091"/>
    <parent link="lbr_link_6"/>
    <child link="lbr_link_7"/>
    <axis xyz="0.0 0.0 1.0"/>
    <limit effort="200" lower="-3.0543261909900763" upper="3.0543261909900763" velocity="2.356194490192345"/>
    <dynamics damping="10.0" friction="0.1"/>
  </joint>
  <link name="lbr_link_7">
    <inertial>
      <origin rpy="0 0 0" xyz="3.0000e-06 -2.0000e-06 1.3782e-02"/>
      <mass value="0.265331"/>
      <inertia ixx="0.000175" ixy="0.0" ixz="0.0" iyy="0.000175" iyz="0.0" izz="0.000306"/>
    </inertial>
    <visual>
      <origin rpy="0 0 0" xyz="0.0 0.0 -1.271"/>
      <geometry>
        <mesh filename="lbr_description/meshes/iiwa14/visual/link_7.dae"/>
      </geometry>
    </visual>
    <collision>
      <origin rpy="0 0 0" xyz="0.0 0.0 -1.271"/>
      <geometry>
        <mesh filename="lbr_description/meshes/iiwa14/collision/link_7.stl"/>
      </geometry>
    </collision>
  </link>

  <!-- Mount + screws -->
  <link name="robotiq_to_lbr_mount">
    <inertial>
      <origin rpy="0 0 0" xyz="0 0 0"/>
      <mass value="0.064"/>
      <inertia ixx="2.0368000000000002e-05" ixy="0.0" ixz="0.0" iyy="2.0368000000000002e-05" iyz="0.0" izz="3.9200000000000004e-05"/>
    </inertial>
    <visual>
      <origin rpy="0 0 0" xyz="0 0 0"/>
      <geometry>
        <mesh filename="lbr_description/meshes/iiwa14/visual/mount.obj"/>
      </geometry>
    </visual>
    <collision>
      <origin rpy="0 0 0" xyz="0 0 0"/>
      <geometry>
        <mesh filename="lbr_description/meshes/iiwa14/collision/mount.stl"/>
      </geometry>
    </collision>
  </link>
  <joint name="lbr_to_mount" type="fixed">
    <parent link="lbr_link_7"/>
    <child link="robotiq_to_lbr_mount"/>
    <origin rpy="0 0 3.141592653589793" xyz="0 0 0.0435"/>
  </joint>

  <!-- Robotiq gripper -->
  <link name="robotiq_link">
      <inertial>
        <origin rpy="0 0 0" xyz="8.625E-08 -4.6583E-06 0.03145"/>
        <mass value="0.22652"/>
        <inertia ixx="0.00020005" ixy="-4.2442E-10" ixz="-2.9069E-10" iyy="0.00017832" iyz="-3.4402E-08" izz="0.00013478"/>
      </inertial>
      <visual>
        <origin rpy="0 0 0" xyz="0 0 0"/>
        <geometry>
          <mesh filename="lbr_description/meshes/robotiq/visual/robotiq_140.obj"/>
        </geometry>
        <material name="">
          <color rgba="0.1 0.1 0.1 1"/>
        </material>
      </visual>
      <collision>
        <origin rpy="0 0 0" xyz="0 0 0"/>
        <geometry>
          <mesh filename="lbr_description/meshes/robotiq/collision/robotiq_140.obj"/>
        </geometry>
      </collision>
    </link>
    <joint name="mount_to_robotiq_link" type="fixed">
      <parent link="robotiq_to_lbr_mount"/>
      <child link="robotiq_link"/>
      <origin rpy="0 0 0" xyz="0 0 0.0056"/>
    </joint>

    <!-- frames for grasping -->
    <!-- https://github.com/NVlabs/GraspGen/blob/main/fig/graspgen_coordinate_convention.png -->
   <link name="tool_center_point_link">
      <inertial>
      <mass value="0.01"/>
      <inertia ixx="0.0001" ixy="0.0" ixz="0.0" iyy="0.0001" iyz="0.0" izz="0.0001"/>
      <origin rpy="0 0 0" xyz="0 0 0"/>
      </inertial>
   </link>
  <joint name="robotiq_tool_center_point_joint" type="fixed">
    <origin rpy="0 0 0.0" xyz="0 0 0.2"/>
    <axis xyz="0 0 1"/>
    <parent link="robotiq_link"/>
    <child link="tool_center_point_link"/>
    </joint>

  <link name="robotiq_base_link">
      <inertial>
      <mass value="0.01"/>
      <inertia ixx="0.0001" ixy="0.0" ixz="0.0" iyy="0.0001" iyz="0.0" izz="0.0001"/>
      <origin rpy="0 0 0" xyz="0 0 0"/>
      </inertial>
   </link>

  <!-- https://github.com/NVlabs/GraspGen/blob/main/config/grippers/robotiq_2f_140.yaml-->
  <joint name="robotiq_tcp_base_offset" type="fixed">
    <origin rpy="0 0 0.0" xyz="0 0 -0.195"/>
    <axis xyz="0 0 1"/>
    <parent link="tool_center_point_link"/>
    <child link="robotiq_base_link"/>
  </joint>

</robot>
